Error in <RootX11IOErrorHandler>: fatal X11 error (connection to server lost?!)

**** Save data and exit application ****

Traceback (most recent call last):
  File "plot_dataMC.py", line 14, in <module>
    from my_funcs import makeDataMCPlot, makePlot
  File "/cvmfs/cms.cern.ch/slc7_amd64_gcc820/lcg/root/6.14.09/lib/ROOT.py", line 461, in _importhook
    return _orig_ihook( name, *args, **kwds )
  File "/uscms_data/d3/peteryou/CMSSW_10_6_4/src/VHanalysis/UtilScripts/my_funcs.py", line 12, in <module>
    colors = [ROOT.kRed, ROOT.kBlack, ROOT.kAzure-4] #ROOT.kBlue
  File "/cvmfs/cms.cern.ch/slc7_amd64_gcc820/lcg/root/6.14.09/lib/ROOT.py", line 564, in __getattr1
    self.__finalSetup()
  File "/cvmfs/cms.cern.ch/slc7_amd64_gcc820/lcg/root/6.14.09/lib/ROOT.py", line 642, in __finalSetup
    if (not _builtin_cppyy and appc.CreatePyROOTApplication()) or _builtin_cppyy:
SystemError: static bool PyROOT::TPyROOTApplication::CreatePyROOTApplication(bool bLoadLibs = kTRUE) =>
    problem in C++; program state has been reset
Error in <RootX11IOErrorHandler>: fatal X11 error (connection to server lost?!)

**** Save data and exit application ****

Traceback (most recent call last):
  File "plot_dataMC.py", line 14, in <module>
    from my_funcs import makeDataMCPlot, makePlot
  File "/cvmfs/cms.cern.ch/slc7_amd64_gcc820/lcg/root/6.14.09/lib/ROOT.py", line 461, in _importhook
    return _orig_ihook( name, *args, **kwds )
  File "/uscms_data/d3/peteryou/CMSSW_10_6_4/src/VHanalysis/UtilScripts/my_funcs.py", line 12, in <module>
    colors = [ROOT.kRed, ROOT.kBlack, ROOT.kAzure-4] #ROOT.kBlue
  File "/cvmfs/cms.cern.ch/slc7_amd64_gcc820/lcg/root/6.14.09/lib/ROOT.py", line 564, in __getattr1
    self.__finalSetup()
  File "/cvmfs/cms.cern.ch/slc7_amd64_gcc820/lcg/root/6.14.09/lib/ROOT.py", line 642, in __finalSetup
    if (not _builtin_cppyy and appc.CreatePyROOTApplication()) or _builtin_cppyy:
SystemError: static bool PyROOT::TPyROOTApplication::CreatePyROOTApplication(bool bLoadLibs = kTRUE) =>
    problem in C++; program state has been reset
